2025-01-28 12:17:22,903 - main - ERROR - Error during initialization: HTTPConnectionPool(host='18.208.243.129', port=5000): Max retries exceeded with url: /validate_key (Caused by ConnectTimeoutError(<urllib3.connection.HTTPConnection object at 0x0000019EF367E1D0>, 'Connection to 18.208.243.129 timed out. (connect timeout=None)'))
2025-01-28 12:17:22,905 - main - ERROR - Traceback (most recent call last):
  File "C:\Users\mande\DOWNLO~1\MACROR~1\MACROR~1\NEW-RL~1.3(C\NEW-RL~1.3(C\urllib3\connection.py", line 174, in _new_conn
  File "C:\Users\mande\DOWNLO~1\MACROR~1\MACROR~1\NEW-RL~1.3(C\NEW-RL~1.3(C\urllib3\util\connection.py", line 85, in create_connection
TimeoutError: [WinError 10060] Ein Verbindungsversuch ist fehlgeschlagen, da die Gegenstelle nach einer bestimmten Zeitspanne nicht richtig reagiert hat, oder die hergestellte Verbindung war fehlerhaft, da der verbundene Host nicht reagiert hat

During handling of the above exception, another exception occurred:

Traceback (most recent call last):
  File "C:\Users\mande\DOWNLO~1\MACROR~1\MACROR~1\NEW-RL~1.3(C\NEW-RL~1.3(C\urllib3\connectionpool.py", line 716, in urlopen
  File "C:\Users\mande\DOWNLO~1\MACROR~1\MACROR~1\NEW-RL~1.3(C\NEW-RL~1.3(C\urllib3\connectionpool.py", line 416, in _make_request
  File "C:\Users\mande\DOWNLO~1\MACROR~1\MACROR~1\NEW-RL~1.3(C\NEW-RL~1.3(C\urllib3\connection.py", line 244, in request
  File "C:\Users\mande\DOWNLO~1\MACROR~1\MACROR~1\NEW-RL~1.3(C\NEW-RL~1.3(C\http\client.py", line 1282, in request
  File "C:\Users\mande\DOWNLO~1\MACROR~1\MACROR~1\NEW-RL~1.3(C\NEW-RL~1.3(C\http\client.py", line 1328, in _send_request
  File "C:\Users\mande\DOWNLO~1\MACROR~1\MACROR~1\NEW-RL~1.3(C\NEW-RL~1.3(C\http\client.py", line 1277, in endheaders
  File "C:\Users\mande\DOWNLO~1\MACROR~1\MACROR~1\NEW-RL~1.3(C\NEW-RL~1.3(C\http\client.py", line 1037, in _send_output
  File "C:\Users\mande\DOWNLO~1\MACROR~1\MACROR~1\NEW-RL~1.3(C\NEW-RL~1.3(C\http\client.py", line 975, in send
  File "C:\Users\mande\DOWNLO~1\MACROR~1\MACROR~1\NEW-RL~1.3(C\NEW-RL~1.3(C\urllib3\connection.py", line 205, in connect
  File "C:\Users\mande\DOWNLO~1\MACROR~1\MACROR~1\NEW-RL~1.3(C\NEW-RL~1.3(C\urllib3\connection.py", line 179, in _new_conn
urllib3.exceptions.ConnectTimeoutError: (<urllib3.connection.HTTPConnection object at 0x0000019EF367E1D0>, 'Connection to 18.208.243.129 timed out. (connect timeout=None)')

During handling of the above exception, another exception occurred:

Traceback (most recent call last):
  File "C:\Users\mande\DOWNLO~1\MACROR~1\MACROR~1\NEW-RL~1.3(C\NEW-RL~1.3(C\requests\adapters.py", line 667, in send
  File "C:\Users\mande\DOWNLO~1\MACROR~1\MACROR~1\NEW-RL~1.3(C\NEW-RL~1.3(C\urllib3\connectionpool.py", line 802, in urlopen
  File "C:\Users\mande\DOWNLO~1\MACROR~1\MACROR~1\NEW-RL~1.3(C\NEW-RL~1.3(C\urllib3\util\retry.py", line 594, in increment
urllib3.exceptions.MaxRetryError: HTTPConnectionPool(host='18.208.243.129', port=5000): Max retries exceeded with url: /validate_key (Caused by ConnectTimeoutError(<urllib3.connection.HTTPConnection object at 0x0000019EF367E1D0>, 'Connection to 18.208.243.129 timed out. (connect timeout=None)'))

During handling of the above exception, another exception occurred:

Traceback (most recent call last):
  File "C:\Users\mande\DOWNLO~1\MACROR~1\MACROR~1\NEW-RL~1.3(C\NEW-RL~1.3(C\main.py", line 125, in initialize_components
  File "C:\Users\mande\DOWNLO~1\MACROR~1\MACROR~1\NEW-RL~1.3(C\NEW-RL~1.3(C\macro_tool.py", line 30, in __init__
  File "C:\Users\mande\DOWNLO~1\MACROR~1\MACROR~1\NEW-RL~1.3(C\NEW-RL~1.3(C\macro_tool.py", line 235, in verify_license
  File "C:\Users\mande\DOWNLO~1\MACROR~1\MACROR~1\NEW-RL~1.3(C\NEW-RL~1.3(C\macro_tool.py", line 225, in is_valid_license_key
  File "C:\Users\mande\DOWNLO~1\MACROR~1\MACROR~1\NEW-RL~1.3(C\NEW-RL~1.3(C\requests\api.py", line 115, in post
  File "C:\Users\mande\DOWNLO~1\MACROR~1\MACROR~1\NEW-RL~1.3(C\NEW-RL~1.3(C\requests\api.py", line 59, in request
  File "C:\Users\mande\DOWNLO~1\MACROR~1\MACROR~1\NEW-RL~1.3(C\NEW-RL~1.3(C\requests\sessions.py", line 589, in request
  File "C:\Users\mande\DOWNLO~1\MACROR~1\MACROR~1\NEW-RL~1.3(C\NEW-RL~1.3(C\requests\sessions.py", line 703, in send
  File "C:\Users\mande\DOWNLO~1\MACROR~1\MACROR~1\NEW-RL~1.3(C\NEW-RL~1.3(C\requests\adapters.py", line 688, in send
requests.exceptions.ConnectTimeout: HTTPConnectionPool(host='18.208.243.129', port=5000): Max retries exceeded with url: /validate_key (Caused by ConnectTimeoutError(<urllib3.connection.HTTPConnection object at 0x0000019EF367E1D0>, 'Connection to 18.208.243.129 timed out. (connect timeout=None)'))

2025-01-28 12:17:32,530 - main - ERROR - Error during initialization: HTTPConnectionPool(host='18.208.243.129', port=5000): Max retries exceeded with url: /validate_key (Caused by ConnectTimeoutError(<urllib3.connection.HTTPConnection object at 0x000001DEA282E1D0>, 'Connection to 18.208.243.129 timed out. (connect timeout=None)'))
2025-01-28 12:17:32,531 - main - ERROR - Traceback (most recent call last):
  File "C:\Users\mande\DOWNLO~1\MACROR~1\MACROR~1\NEW-RL~1.3(C\NEW-RL~1.3(C\urllib3\connection.py", line 174, in _new_conn
  File "C:\Users\mande\DOWNLO~1\MACROR~1\MACROR~1\NEW-RL~1.3(C\NEW-RL~1.3(C\urllib3\util\connection.py", line 85, in create_connection
TimeoutError: [WinError 10060] Ein Verbindungsversuch ist fehlgeschlagen, da die Gegenstelle nach einer bestimmten Zeitspanne nicht richtig reagiert hat, oder die hergestellte Verbindung war fehlerhaft, da der verbundene Host nicht reagiert hat

During handling of the above exception, another exception occurred:

Traceback (most recent call last):
  File "C:\Users\mande\DOWNLO~1\MACROR~1\MACROR~1\NEW-RL~1.3(C\NEW-RL~1.3(C\urllib3\connectionpool.py", line 716, in urlopen
  File "C:\Users\mande\DOWNLO~1\MACROR~1\MACROR~1\NEW-RL~1.3(C\NEW-RL~1.3(C\urllib3\connectionpool.py", line 416, in _make_request
  File "C:\Users\mande\DOWNLO~1\MACROR~1\MACROR~1\NEW-RL~1.3(C\NEW-RL~1.3(C\urllib3\connection.py", line 244, in request
  File "C:\Users\mande\DOWNLO~1\MACROR~1\MACROR~1\NEW-RL~1.3(C\NEW-RL~1.3(C\http\client.py", line 1282, in request
  File "C:\Users\mande\DOWNLO~1\MACROR~1\MACROR~1\NEW-RL~1.3(C\NEW-RL~1.3(C\http\client.py", line 1328, in _send_request
  File "C:\Users\mande\DOWNLO~1\MACROR~1\MACROR~1\NEW-RL~1.3(C\NEW-RL~1.3(C\http\client.py", line 1277, in endheaders
  File "C:\Users\mande\DOWNLO~1\MACROR~1\MACROR~1\NEW-RL~1.3(C\NEW-RL~1.3(C\http\client.py", line 1037, in _send_output
  File "C:\Users\mande\DOWNLO~1\MACROR~1\MACROR~1\NEW-RL~1.3(C\NEW-RL~1.3(C\http\client.py", line 975, in send
  File "C:\Users\mande\DOWNLO~1\MACROR~1\MACROR~1\NEW-RL~1.3(C\NEW-RL~1.3(C\urllib3\connection.py", line 205, in connect
  File "C:\Users\mande\DOWNLO~1\MACROR~1\MACROR~1\NEW-RL~1.3(C\NEW-RL~1.3(C\urllib3\connection.py", line 179, in _new_conn
urllib3.exceptions.ConnectTimeoutError: (<urllib3.connection.HTTPConnection object at 0x000001DEA282E1D0>, 'Connection to 18.208.243.129 timed out. (connect timeout=None)')

During handling of the above exception, another exception occurred:

Traceback (most recent call last):
  File "C:\Users\mande\DOWNLO~1\MACROR~1\MACROR~1\NEW-RL~1.3(C\NEW-RL~1.3(C\requests\adapters.py", line 667, in send
  File "C:\Users\mande\DOWNLO~1\MACROR~1\MACROR~1\NEW-RL~1.3(C\NEW-RL~1.3(C\urllib3\connectionpool.py", line 802, in urlopen
  File "C:\Users\mande\DOWNLO~1\MACROR~1\MACROR~1\NEW-RL~1.3(C\NEW-RL~1.3(C\urllib3\util\retry.py", line 594, in increment
urllib3.exceptions.MaxRetryError: HTTPConnectionPool(host='18.208.243.129', port=5000): Max retries exceeded with url: /validate_key (Caused by ConnectTimeoutError(<urllib3.connection.HTTPConnection object at 0x000001DEA282E1D0>, 'Connection to 18.208.243.129 timed out. (connect timeout=None)'))

During handling of the above exception, another exception occurred:

Traceback (most recent call last):
  File "C:\Users\mande\DOWNLO~1\MACROR~1\MACROR~1\NEW-RL~1.3(C\NEW-RL~1.3(C\main.py", line 125, in initialize_components
  File "C:\Users\mande\DOWNLO~1\MACROR~1\MACROR~1\NEW-RL~1.3(C\NEW-RL~1.3(C\macro_tool.py", line 30, in __init__
  File "C:\Users\mande\DOWNLO~1\MACROR~1\MACROR~1\NEW-RL~1.3(C\NEW-RL~1.3(C\macro_tool.py", line 235, in verify_license
  File "C:\Users\mande\DOWNLO~1\MACROR~1\MACROR~1\NEW-RL~1.3(C\NEW-RL~1.3(C\macro_tool.py", line 225, in is_valid_license_key
  File "C:\Users\mande\DOWNLO~1\MACROR~1\MACROR~1\NEW-RL~1.3(C\NEW-RL~1.3(C\requests\api.py", line 115, in post
  File "C:\Users\mande\DOWNLO~1\MACROR~1\MACROR~1\NEW-RL~1.3(C\NEW-RL~1.3(C\requests\api.py", line 59, in request
  File "C:\Users\mande\DOWNLO~1\MACROR~1\MACROR~1\NEW-RL~1.3(C\NEW-RL~1.3(C\requests\sessions.py", line 589, in request
  File "C:\Users\mande\DOWNLO~1\MACROR~1\MACROR~1\NEW-RL~1.3(C\NEW-RL~1.3(C\requests\sessions.py", line 703, in send
  File "C:\Users\mande\DOWNLO~1\MACROR~1\MACROR~1\NEW-RL~1.3(C\NEW-RL~1.3(C\requests\adapters.py", line 688, in send
requests.exceptions.ConnectTimeout: HTTPConnectionPool(host='18.208.243.129', port=5000): Max retries exceeded with url: /validate_key (Caused by ConnectTimeoutError(<urllib3.connection.HTTPConnection object at 0x000001DEA282E1D0>, 'Connection to 18.208.243.129 timed out. (connect timeout=None)'))

2025-01-28 12:17:50,960 - main - ERROR - Error during initialization: HTTPConnectionPool(host='18.208.243.129', port=5000): Max retries exceeded with url: /validate_key (Caused by ConnectTimeoutError(<urllib3.connection.HTTPConnection object at 0x000002517F1CE1D0>, 'Connection to 18.208.243.129 timed out. (connect timeout=None)'))
2025-01-28 12:17:50,961 - main - ERROR - Traceback (most recent call last):
  File "C:\Users\mande\DOWNLO~1\MACROR~1\MACROR~1\NEW-RL~1.3(C\NEW-RL~1.3(C\urllib3\connection.py", line 174, in _new_conn
  File "C:\Users\mande\DOWNLO~1\MACROR~1\MACROR~1\NEW-RL~1.3(C\NEW-RL~1.3(C\urllib3\util\connection.py", line 85, in create_connection
TimeoutError: [WinError 10060] Ein Verbindungsversuch ist fehlgeschlagen, da die Gegenstelle nach einer bestimmten Zeitspanne nicht richtig reagiert hat, oder die hergestellte Verbindung war fehlerhaft, da der verbundene Host nicht reagiert hat

During handling of the above exception, another exception occurred:

Traceback (most recent call last):
  File "C:\Users\mande\DOWNLO~1\MACROR~1\MACROR~1\NEW-RL~1.3(C\NEW-RL~1.3(C\urllib3\connectionpool.py", line 716, in urlopen
  File "C:\Users\mande\DOWNLO~1\MACROR~1\MACROR~1\NEW-RL~1.3(C\NEW-RL~1.3(C\urllib3\connectionpool.py", line 416, in _make_request
  File "C:\Users\mande\DOWNLO~1\MACROR~1\MACROR~1\NEW-RL~1.3(C\NEW-RL~1.3(C\urllib3\connection.py", line 244, in request
  File "C:\Users\mande\DOWNLO~1\MACROR~1\MACROR~1\NEW-RL~1.3(C\NEW-RL~1.3(C\http\client.py", line 1282, in request
  File "C:\Users\mande\DOWNLO~1\MACROR~1\MACROR~1\NEW-RL~1.3(C\NEW-RL~1.3(C\http\client.py", line 1328, in _send_request
  File "C:\Users\mande\DOWNLO~1\MACROR~1\MACROR~1\NEW-RL~1.3(C\NEW-RL~1.3(C\http\client.py", line 1277, in endheaders
  File "C:\Users\mande\DOWNLO~1\MACROR~1\MACROR~1\NEW-RL~1.3(C\NEW-RL~1.3(C\http\client.py", line 1037, in _send_output
  File "C:\Users\mande\DOWNLO~1\MACROR~1\MACROR~1\NEW-RL~1.3(C\NEW-RL~1.3(C\http\client.py", line 975, in send
  File "C:\Users\mande\DOWNLO~1\MACROR~1\MACROR~1\NEW-RL~1.3(C\NEW-RL~1.3(C\urllib3\connection.py", line 205, in connect
  File "C:\Users\mande\DOWNLO~1\MACROR~1\MACROR~1\NEW-RL~1.3(C\NEW-RL~1.3(C\urllib3\connection.py", line 179, in _new_conn
urllib3.exceptions.ConnectTimeoutError: (<urllib3.connection.HTTPConnection object at 0x000002517F1CE1D0>, 'Connection to 18.208.243.129 timed out. (connect timeout=None)')

During handling of the above exception, another exception occurred:

Traceback (most recent call last):
  File "C:\Users\mande\DOWNLO~1\MACROR~1\MACROR~1\NEW-RL~1.3(C\NEW-RL~1.3(C\requests\adapters.py", line 667, in send
  File "C:\Users\mande\DOWNLO~1\MACROR~1\MACROR~1\NEW-RL~1.3(C\NEW-RL~1.3(C\urllib3\connectionpool.py", line 802, in urlopen
  File "C:\Users\mande\DOWNLO~1\MACROR~1\MACROR~1\NEW-RL~1.3(C\NEW-RL~1.3(C\urllib3\util\retry.py", line 594, in increment
urllib3.exceptions.MaxRetryError: HTTPConnectionPool(host='18.208.243.129', port=5000): Max retries exceeded with url: /validate_key (Caused by ConnectTimeoutError(<urllib3.connection.HTTPConnection object at 0x000002517F1CE1D0>, 'Connection to 18.208.243.129 timed out. (connect timeout=None)'))

During handling of the above exception, another exception occurred:

Traceback (most recent call last):
  File "C:\Users\mande\DOWNLO~1\MACROR~1\MACROR~1\NEW-RL~1.3(C\NEW-RL~1.3(C\main.py", line 125, in initialize_components
  File "C:\Users\mande\DOWNLO~1\MACROR~1\MACROR~1\NEW-RL~1.3(C\NEW-RL~1.3(C\macro_tool.py", line 30, in __init__
  File "C:\Users\mande\DOWNLO~1\MACROR~1\MACROR~1\NEW-RL~1.3(C\NEW-RL~1.3(C\macro_tool.py", line 235, in verify_license
  File "C:\Users\mande\DOWNLO~1\MACROR~1\MACROR~1\NEW-RL~1.3(C\NEW-RL~1.3(C\macro_tool.py", line 225, in is_valid_license_key
  File "C:\Users\mande\DOWNLO~1\MACROR~1\MACROR~1\NEW-RL~1.3(C\NEW-RL~1.3(C\requests\api.py", line 115, in post
  File "C:\Users\mande\DOWNLO~1\MACROR~1\MACROR~1\NEW-RL~1.3(C\NEW-RL~1.3(C\requests\api.py", line 59, in request
  File "C:\Users\mande\DOWNLO~1\MACROR~1\MACROR~1\NEW-RL~1.3(C\NEW-RL~1.3(C\requests\sessions.py", line 589, in request
  File "C:\Users\mande\DOWNLO~1\MACROR~1\MACROR~1\NEW-RL~1.3(C\NEW-RL~1.3(C\requests\sessions.py", line 703, in send
  File "C:\Users\mande\DOWNLO~1\MACROR~1\MACROR~1\NEW-RL~1.3(C\NEW-RL~1.3(C\requests\adapters.py", line 688, in send
requests.exceptions.ConnectTimeout: HTTPConnectionPool(host='18.208.243.129', port=5000): Max retries exceeded with url: /validate_key (Caused by ConnectTimeoutError(<urllib3.connection.HTTPConnection object at 0x000002517F1CE1D0>, 'Connection to 18.208.243.129 timed out. (connect timeout=None)'))

2025-01-28 13:02:27,763 - main - ERROR - Error during initialization: HTTPConnectionPool(host='18.208.243.129', port=5000): Max retries exceeded with url: /validate_key (Caused by ConnectTimeoutError(<urllib3.connection.HTTPConnection object at 0x000002697CEA21A0>, 'Connection to 18.208.243.129 timed out. (connect timeout=None)'))
2025-01-28 13:02:27,764 - main - ERROR - Traceback (most recent call last):
  File "C:\Users\mande\DOWNLO~1\MACROR~1\MACROR~1\NEW-RL~1.3(C\NEW-RL~1.3(C\urllib3\connection.py", line 174, in _new_conn
  File "C:\Users\mande\DOWNLO~1\MACROR~1\MACROR~1\NEW-RL~1.3(C\NEW-RL~1.3(C\urllib3\util\connection.py", line 85, in create_connection
TimeoutError: [WinError 10060] Ein Verbindungsversuch ist fehlgeschlagen, da die Gegenstelle nach einer bestimmten Zeitspanne nicht richtig reagiert hat, oder die hergestellte Verbindung war fehlerhaft, da der verbundene Host nicht reagiert hat

During handling of the above exception, another exception occurred:

Traceback (most recent call last):
  File "C:\Users\mande\DOWNLO~1\MACROR~1\MACROR~1\NEW-RL~1.3(C\NEW-RL~1.3(C\urllib3\connectionpool.py", line 716, in urlopen
  File "C:\Users\mande\DOWNLO~1\MACROR~1\MACROR~1\NEW-RL~1.3(C\NEW-RL~1.3(C\urllib3\connectionpool.py", line 416, in _make_request
  File "C:\Users\mande\DOWNLO~1\MACROR~1\MACROR~1\NEW-RL~1.3(C\NEW-RL~1.3(C\urllib3\connection.py", line 244, in request
  File "C:\Users\mande\DOWNLO~1\MACROR~1\MACROR~1\NEW-RL~1.3(C\NEW-RL~1.3(C\http\client.py", line 1282, in request
  File "C:\Users\mande\DOWNLO~1\MACROR~1\MACROR~1\NEW-RL~1.3(C\NEW-RL~1.3(C\http\client.py", line 1328, in _send_request
  File "C:\Users\mande\DOWNLO~1\MACROR~1\MACROR~1\NEW-RL~1.3(C\NEW-RL~1.3(C\http\client.py", line 1277, in endheaders
  File "C:\Users\mande\DOWNLO~1\MACROR~1\MACROR~1\NEW-RL~1.3(C\NEW-RL~1.3(C\http\client.py", line 1037, in _send_output
  File "C:\Users\mande\DOWNLO~1\MACROR~1\MACROR~1\NEW-RL~1.3(C\NEW-RL~1.3(C\http\client.py", line 975, in send
  File "C:\Users\mande\DOWNLO~1\MACROR~1\MACROR~1\NEW-RL~1.3(C\NEW-RL~1.3(C\urllib3\connection.py", line 205, in connect
  File "C:\Users\mande\DOWNLO~1\MACROR~1\MACROR~1\NEW-RL~1.3(C\NEW-RL~1.3(C\urllib3\connection.py", line 179, in _new_conn
urllib3.exceptions.ConnectTimeoutError: (<urllib3.connection.HTTPConnection object at 0x000002697CEA21A0>, 'Connection to 18.208.243.129 timed out. (connect timeout=None)')

During handling of the above exception, another exception occurred:

Traceback (most recent call last):
  File "C:\Users\mande\DOWNLO~1\MACROR~1\MACROR~1\NEW-RL~1.3(C\NEW-RL~1.3(C\requests\adapters.py", line 667, in send
  File "C:\Users\mande\DOWNLO~1\MACROR~1\MACROR~1\NEW-RL~1.3(C\NEW-RL~1.3(C\urllib3\connectionpool.py", line 802, in urlopen
  File "C:\Users\mande\DOWNLO~1\MACROR~1\MACROR~1\NEW-RL~1.3(C\NEW-RL~1.3(C\urllib3\util\retry.py", line 594, in increment
urllib3.exceptions.MaxRetryError: HTTPConnectionPool(host='18.208.243.129', port=5000): Max retries exceeded with url: /validate_key (Caused by ConnectTimeoutError(<urllib3.connection.HTTPConnection object at 0x000002697CEA21A0>, 'Connection to 18.208.243.129 timed out. (connect timeout=None)'))

During handling of the above exception, another exception occurred:

Traceback (most recent call last):
  File "C:\Users\mande\DOWNLO~1\MACROR~1\MACROR~1\NEW-RL~1.3(C\NEW-RL~1.3(C\main.py", line 125, in initialize_components
  File "C:\Users\mande\DOWNLO~1\MACROR~1\MACROR~1\NEW-RL~1.3(C\NEW-RL~1.3(C\macro_tool.py", line 30, in __init__
  File "C:\Users\mande\DOWNLO~1\MACROR~1\MACROR~1\NEW-RL~1.3(C\NEW-RL~1.3(C\macro_tool.py", line 235, in verify_license
  File "C:\Users\mande\DOWNLO~1\MACROR~1\MACROR~1\NEW-RL~1.3(C\NEW-RL~1.3(C\macro_tool.py", line 225, in is_valid_license_key
  File "C:\Users\mande\DOWNLO~1\MACROR~1\MACROR~1\NEW-RL~1.3(C\NEW-RL~1.3(C\requests\api.py", line 115, in post
  File "C:\Users\mande\DOWNLO~1\MACROR~1\MACROR~1\NEW-RL~1.3(C\NEW-RL~1.3(C\requests\api.py", line 59, in request
  File "C:\Users\mande\DOWNLO~1\MACROR~1\MACROR~1\NEW-RL~1.3(C\NEW-RL~1.3(C\requests\sessions.py", line 589, in request
  File "C:\Users\mande\DOWNLO~1\MACROR~1\MACROR~1\NEW-RL~1.3(C\NEW-RL~1.3(C\requests\sessions.py", line 703, in send
  File "C:\Users\mande\DOWNLO~1\MACROR~1\MACROR~1\NEW-RL~1.3(C\NEW-RL~1.3(C\requests\adapters.py", line 688, in send
requests.exceptions.ConnectTimeout: HTTPConnectionPool(host='18.208.243.129', port=5000): Max retries exceeded with url: /validate_key (Caused by ConnectTimeoutError(<urllib3.connection.HTTPConnection object at 0x000002697CEA21A0>, 'Connection to 18.208.243.129 timed out. (connect timeout=None)'))

